Workbook

Sheet Start_Here
A1: PRICING INTELLIGENCE — INITIAL DATA WORKBOOK
A3: Purpose | B3: Capture company context, economics, operating constraints and historical price-demand data for the pricing engine.
A4: Default period | B4: Monthly is the default for most businesses. Use the same period for cost planning, target volume and fixed costs.
A5: Next step | B5: Step 2 will validate the historical data and run EDA before demand forecasting, elasticity and causal estimation.
A6: Important | B6: Do not guess elasticity or willingness-to-pay here. Estimate them later or use documented external priors.
A7: Packaging | B7: Packaging that scales with units is normally variable cost. Keep it separate so its economics are visible.
A8: Labour | B8: Permanent salaries are generally fixed. Piece-rate/output labour is variable. Overtime/extra shifts can be step or semi-variable.
A9: Historical minimum | B9: Date + product + price + quantity. Revenue, competitor price, promotion, inventory, location and channel materially improve the model.
A10: Tabs | B10: Company_Context | Cost_Structure | Constraints | Historical_Data | Definitions | Dashboard

Sheet Company_Context
A1: 01 — COMPANY & PRODUCT CONTEXT
A3: Company & Product | E3: Market Position & Price Leader
A4: Field | B4: Input | C4: Guidance | E4: Field | F4: Input | G4: Derived / Guidance | H4: Status
A5: Company name | B5: bishanlal babulal | C5: Legal or operating brand name | E5: Price leader? | F5: no(rank 6) | G5: If No, enter leader below | H5: =IF(F5="Yes","Leader selected","Follower setup") -> Follower setup
A6: Business category | B6: food | C6: e.g. Packaged Food, Chemicals, SaaS | E6: Price leader / competitor | F6: bikaji | G6: Named reference competitor | H6: =IF(F5="No",IF(F6<>"","OK","Enter leader name"),"N/A") -> N/A
A7: Product name | B7: 1kg bikaneri bhujia | C7: Primary product being priced | E7: Leader current base price | F7: 260 | G7: Before tax/discount
A8: Product type | B8: fmcg | C8: FMCG, B2B service, software, industrial product, etc. | E8: Our current base price | F8: 280 | G8: Before tax/discount
A9: Market / country | B9: India | C9: Primary market | E9: Price gap | F9: =F8-F7 -> 20 | G9: Our price − leader price | H9: =IF(F5="Yes","N/A",IF(F7>0,"Calculated","—")) -> Calculated
A10: Primary channel | B10: Both | C10: Online / Offline / Both | E10: Relative price | F10: =IF(F8>0,F8/F7,0) -> 1.0769231 | G10: Our price ÷ leader price
A11: primary region | B11: rajasthan particulary bikaner | E11: Positioning note | F11: premium | G11: Premium / parity / value / unknown
A12: overall region | B12: india
A14: Current Price & Tax
A15: Field | B15: Input | C15: Guidance
A16: Current base price(before tax) | B16: 267 | C16: Price before GST/tax
A17: GST / tax rate | B17: 5 | C17: Applicable rate
A18: Current discount | B18: 0 | C18: Optional current discount
A19: Tax amount / unit | B19: =B16*B17/100 -> 13.35 | C19: Calculated
A20: Price after tax | B20: =B16+B19 -> 280.35 | C20: Calculated before discount
A21: Current discount | B21: 0 | C21: assumption
A22: Effective customer price | B22: =B20*(1-B18/100) -> 280.35 | C22: After tax and current discount
A23: retailer commission | B23: 0.1 | C23: assuming : taking an avg as talk with other retailers

Sheet Cost_Structure
A1: 02 — COST STRUCTURE
A3: Cost Planning Period
A4: Field | B4: Input | C4: Unit | D4: Guidance
A5: Cost period | B5: Monthly | C5: — | D5: Same period used for fixed cost + target volume
A6: current volume production | B6: 15000 | C6: units / period | D6: saleable volume for planning/allocation
A7: Fixed cost / selected period | B7: =C30 -> 448000 | C7: ₹ / period | D7: Calculated from fixed-cost section below
A8: current profit / unit | B8: =B41 -> 56.433333 | C8: ₹ / unit | D8: Optional cost-plus reference, not the final optimized price
A9: unit sold | B9: 13000 | C9: unit/period
A10: Variable Costs — normally scale with units
A11: Cost type | B11: Cost item | C11: ₹ / unit | D11: Included? | E11: Examples / guidance
A12: Variable | B12: Raw material / ingredients | C12: =E61 -> 104 | D12: Yes | E12: Inputs consumed per unit(mainly in oil)
A13: Variable | B13: Packaging | C13: 20 | D13: Yes | E13: Pouch, carton, label, seal, bottle, cap, tray
A14: Variable | B14: karigar | C14: 7 | D14: Yes | E14: output-linked labour
A15: Variable | B15: Logistics / fulfilment | C15: 20 | D15: Yes | E15: Per-unit freight, delivery or fulfilment
A16: Variable | B16: Sales / payment fees | C16: =Company_Context!B16*0.1 -> 26.7 | D16: Yes | E16: Commission, marketplace fee, payment fee of the sales man, distributors
A17: Variable | B17: cost of electricty | C17: 3 | D17: Optional | E17: Any other per-unit cost
B18: Total variable cost / unit | C18: =SUM(C12:C17) -> 180.7
B19: Contribution at current base price | C19: =Company_Context!B16-C18 -> 86.3 | E19: Current base price − variable cost
A21: Fixed Costs — generally stable within the selected period
A22: Cost type | B22: Cost item | C22: ₹ / selected period | D22: Included? | E22: Examples / guidance
A23: Fixed | B23: Rent / facility | C23: 40000 | D23: Yes | E23: Factory, warehouse, office rent
A24: Fixed | B24: Permanent salaries | C24: =D54 -> 310000 | D24: Yes | E24: Management/admin/production salaries that do not scale directly with units
A25: Fixed | B25: electricity | C25: 70000 | D25: yes | E25: cost of the electricity(excluding the frying )
A26: Fixed | B26: Administrative expenses | C26: 3000 | D26: yes | E26: Office/admin overhead
A27: fixed | B27: returns/ damaged | C27: 5000 | D27: yes | E27: usually not very much around 10 boxes per month 10 damaged total 20
A28: fixed | B28: marketing promotion | C28: 10000 | D28: Optional | E28: instagram , banners ads
A29: Fixed | B29: Other fixed costs | C29: 10000 | D29: Optional | E29: Other stable operating costs
A30: fixed | B30: Total fixed cost / period | C30: =SUM(C23:C29) -> 448000
B31: Fixed cost / target unit | C31: =IF(B6>0,C30/B6,0) -> 29.866667 | E31: Total fixed cost ÷ volume
A34: Cost Reference Outputs
A35: Metric | B35: Formula output | C35: Why it matters | D35: Reference
A36: Variable cost / unit | B36: =C18 -> 180.7 | C36: Economic contribution floor | D36: Used in profit optimization
A37: Fixed cost / period | B37: =C30 -> 448000 | C37: Period-level operating obligation | D37: Keep separate from variable cost
A38: Fixed cost / target unit | B38: =C31 -> 29.866667 | C38: Useful for full-cost / break-even analysis | D38: Reference only
A39: Indicative full cost / unit | B39: =B36+B38 -> 210.56667 | C39: Variable + allocated fixed cost | D39: Cost-plus benchmark, not final optimized price
A40: Current contribution / unit | B40: =Company_Context!B16-B36 -> 86.3 | C40: Base price − variable cost | D40: Margin analysis
A41: profit per box | B41: =Company_Context!B16-B39 -> 56.433333
A47: salaries breakdown
A48: role | B48: no. | C48: salaries | D48: final cost
A49: C.A | B49: 1 | C49: 50000 | D49: =B49*C49 -> 50000
...

Sheet competitive_analysis
B2: Competitive data: 1 kg packs, shelf price (MRP = selling price)
B3: Blue = input. Perception, quality and taste scores are ASSUMPTIONS from the owner's experience (no survey, no sample); treat results as a diagnostic, not evidence.
B5: Brand | C5: Role | D5: Pack (kg) | E5: Shelf price (₹) | F5: Perception (0-10) | G5: Quality (0-10) | H5: Taste (0-10) | I5: Composite benefit | J5: Price per kg (₹) | K5: Gap vs ours (₹) | L5: Relative to leader | M5: Price per benefit point (₹)
B6: Bikaji | C6: Leader | D6: 1 | E6: 260 | F6: 9 | G6: 7 | H6: 8.5 | I6: 8.1666667 | J6: 260 | K6: -20 | L6: 1 | M6: 31.836735
B7: Haldiram | C7: Competitor | D7: 1 | E7: 270 | F7: 8.5 | G7: 7 | H7: 8 | I7: 7.8333333 | J7: 270 | K7: -10 | L7: 1.0384615 | M7: 34.468085
B8: Bikano | C8: Competitor | D8: 1 | E8: 280 | F8: 8 | G8: 8 | H8: 8.5 | I8: 8.1666667 | J8: 280 | K8: 0 | L8: 1.0769231 | M8: 34.285714
B9: Bhikaram Chandmal | C9: Competitor (local) | D9: 1 | E9: 250 | F9: 8.5 | G9: 8 | H9: 8.8 | I9: 8.4333333 | J9: 250 | K9: -30 | L9: 0.96153846 | M9: 29.644269
B10: Bishanlal Babulal | C10: Our brand | D10: 1 | E10: 280 | F10: 9 | G10: 8 | H10: 9 | I10: 8.6666667 | J10: 280 | K10: 0 | L10: 1.0769231 | M10: 32.307692
B11: Composite = simple average of perception, quality and taste (equal weights are an assumption).
B13: Fit-line helper (competitors only) | C13: Benefit (x) | D13: Fair price (y)
B14: Left end | C14: 7.7333333 | D14: 278.03681
B15: Right end | C15: 8.7666667 | D15: 245.70552
B37: Candidate prices vs the market
B38: Shelf price (₹) | C38: Gap vs leader (₹) | D38: Relative to leader | E38: Relative to competitor avg | F38: Cheaper competitors (of 4) | G38: Within leader cap | H38: Feasibility result
B39: 259 | C39: -1 | D39: 0.99615385 | E39: 0.97735849 | F39: 1 | G39: Yes | H39: Breaks step limit
B40: 266.33 | C40: 6.33 | D40: 1.0243462 | E40: 1.0050189 | F40: 2 | G40: Yes | H40: Feasible
B41: 269 | C41: 9 | D41: 1.0346154 | E41: 1.0150943 | F41: 2 | G41: Yes | H41: Feasible
B42: 272 | C42: 12 | D42: 1.0461538 | E42: 1.0264151 | F42: 3 | G42: Yes | H42: Feasible
B43: 275 | C43: 15 | D43: 1.0576923 | E43: 1.0377358 | F43: 3 | G43: Yes | H43: Feasible
B44: 279 | C44: 19 | D44: 1.0730769 | E44: 1.0528302 | F44: 3 | G44: Yes | H44: Feasible
B45: 280 | C45: 20 | D45: 1.0769231 | E45: 1.0566038 | F45: 3 | G45: Yes | H45: Feasible
B46: 289 | C46: 29 | D46: 1.1115385 | E46: 1.090566 | F46: 4 | G46: No | H46: Needs new MRP

Sheet constraints
A1: Constraint | B1: Value | C1: Unit | D1: Basis
A2: Other variable cost (excl. retailer margin) | B2: 154 | C2: ₹ / unit | D2: Total variable cost minus retailer margin
A3: Retailer margin | B3: 0.1 | C3: % of price | D3: Scales with price, not a flat ₹27
A4: Zero-contribution price (safety stop) | B4: 171.11111 | C4: ₹ pre-tax | D4: Other variable cost ÷ (1 − margin)
A5: Full-cost break-even price (reference) | B5: 209.40171 | C5: ₹ pre-tax | D5: Covers variable and fixed cost at current volume
A6: MRP, shelf | B6: 280 | C6: ₹ shelf | D6: Legal cap
A7: MRP, pre-tax equivalent (price ceiling) | B7: 266.66667 | C7: ₹ pre-tax | D7: MRP ÷ (1 + GST)
A8: Step-limit low | B8: 253.65 | C8: ₹ pre-tax | D8: Current price less max decrease
A9: Step-limit high | B9: 275 | C9: ₹ pre-tax | D9: Current price plus max increase
A10: min-limit MRP | B10: 265 | C10: post tax | D10: current price plus gst
A11: max-limit MRP | B11: 288 | C11: post tax | D11: max price + gst
A12: max volume | B12: 17000
A13: min volume | B13: 13000
A14: minimum profit | B14: 650000
A15: max profit based on max volume | B15: 850000
A16: shelf life | B16: 6 months
A17: price -bandwidth | B17: 265-288
A18: Price review cadence | B18: Monthly | D18: Governance
A19: Legal / tax | B19: GST 5%; price must not exceed printed MRP | D19: Verify rate against current CBIC schedule

Sheet data_historical
A1: week_start | B1: shelf_price | C1: leader_price | D1: other_comp_avg_price | E1: festival | F1: oil_price_per_kg | G1: other_variable_cost | H1: price_change | I1: units_sold | J1: distribution | K1: distribution | L1: promotion | M1: log price | N1: log_leader_price | O1: other_comp | P1: log_units_sold | Q1: festival_peak | R1: festival_buildup | S1: units_sold_old | T1: log_distribution | U1: log_promotion
A2: 45201 | B2: 220 | C2: 200 | D2: 216.67 | F2: 100.72 | G2: 141.01 | I2: 2375 | J2: =K2/2 -> 49.5 | K2: 99 | L2: 5 | M2: 5.3936275 | N2: 5.2983174 | O2: 5.3783755 | P2: 7.7727527 | Q2: 0 | R2: 0 | S2: 2141 | T2: 4.5938059 | U2: 2.1860513
A3: 45208 | B3: 220 | C3: 200 | D3: 216.67 | E3: Diwali (build-up) | F3: 100.78 | G3: 141.09 | I3: 3110 | J3: =K3/2 -> 49 | K3: 98 | L3: 5 | M3: 5.3936275 | N3: 5.2983174 | O3: 5.3783755 | P3: 8.042378 | Q3: 0 | R3: 1 | S3: 2536 | T3: 4.5894472 | U3: 2.4484155
A4: 45215 | B4: 220 | C4: 200 | D4: 216.67 | E4: Diwali (build-up) | F4: 100.84 | G4: 141.17 | I4: 3133 | J4: =K4/2 -> 48.5 | K4: 97 | L4: 6 | M4: 5.3936275 | N4: 5.2983174 | O4: 5.3783755 | P4: 8.0497463 | Q4: 0 | R4: 1 | S4: 3487 | T4: 4.5797498 | U4: 2.4150205
A5: 45222 | B5: 220 | C5: 200 | D5: 216.67 | E5: Diwali (build-up) | F5: 100.89 | G5: 141.25 | I5: 3285 | J5: =K5/2 -> 49.5 | K5: 99 | L5: 5 | M5: 5.3936275 | N5: 5.2983174 | O5: 5.3783755 | P5: 8.0971219 | Q5: 0 | R5: 1 | S5: 4580 | T5: 4.5911727 | U5: 2.3253246
A6: 45229 | B6: 220 | C6: 200 | D6: 216.67 | E6: Diwali (build-up) | F6: 100.95 | G6: 141.33 | I6: 3403 | J6: =K6/2 -> 50 | K6: 100 | L6: 4 | M6: 5.3936275 | N6: 5.2983174 | O6: 5.3783755 | P6: 8.1324127 | Q6: 0 | R6: 1 | S6: 4856 | T6: 4.6085644 | U6: 2.5265283
A7: 45236 | B7: 220 | C7: 200 | D7: 216.67 | E7: Diwali (peak week) | F7: 101.01 | G7: 141.41 | I7: 4589 | J7: =K7/2 -> 50.5 | K7: 101 | L7: 6 | M7: 5.3936275 | N7: 5.2983174 | O7: 5.3783755 | P7: 8.4314174 | Q7: 1 | R7: 0 | S7: 4395 | T7: 4.6173952 | U7: 2.6056483
A8: 45243 | B8: 220 | C8: 200 | D8: 216.67 | F8: 101.07 | G8: 141.49 | I8: 2473 | J8: =K8/2 -> 51 | K8: 102 | L8: 4 | M8: 5.3936275 | N8: 5.2983174 | O8: 5.3783755 | P8: 7.8131873 | Q8: 0 | R8: 0 | S8: 1892 | T8: 4.6200588 | U8: 2.313525
A9: 45250 | B9: 220 | C9: 200 | D9: 216.67 | F9: 101.12 | G9: 141.57 | I9: 2427 | J9: =K9/2 -> 51 | K9: 102 | L9: 5 | M9: 5.3936275 | N9: 5.2983174 | O9: 5.3783755 | P9: 7.7944112 | Q9: 0 | R9: 0 | S9: 2116 | T9: 4.6207482 | U9: 2.2491843
A10: 45257 | B10: 220 | C10: 200 | D10: 216.67 | F10: 101.18 | G10: 141.65 | I10: 2370 | J10: =K10/2 -> 50.5 | K10: 101 | L10: 6 | M10: 5.3936275 | N10: 5.2983174 | O10: 5.3783755 | P10: 7.7706452 | Q10: 0 | R10: 0 | S10: 2283 | T10: 4.6145263 | U10: 2.346602
A11: 45264 | B11: 220 | C11: 200 | D11: 216.67 | F11: 101.24 | G11: 141.74 | I11: 2381 | J11: =K11/2 -> 50 | K11: 100 | L11: 6 | M11: 5.3936275 | N11: 5.2983174 | O11: 5.3783755 | P11: 7.7752758 | Q11: 0 | R11: 0 | S11: 2162 | T11: 4.6056701 | U11: 2.2679936
A12: 45271 | B12: 220 | C12: 200 | D12: 216.67 | F12: 101.3 | G12: 141.82 | I12: 2641 | J12: =K12/2 -> 50 | K12: 100 | L12: 7 | M12: 5.3936275 | N12: 5.2983174 | O12: 5.3783755 | P12: 7.8789129 | Q12: 0 | R12: 0 | S12: 2433 | T12: 4.6095605 | U12: 2.3005831
A13: 45278 | B13: 220 | C13: 200 | D13: 216.67 | F13: 101.35 | G13: 141.9 | I13: 2344 | J13: =K13/2 -> 49 | K13: 98 | L13: 6 | M13: 5.3936275 | N13: 5.2983174 | O13: 5.3783755 | P13: 7.7596142 | Q13: 0 | R13: 0 | S13: 2505 | T13: 4.5814921 | U13: 2.2246236
A14: 45285 | B14: 220 | C14: 200 | D14: 216.67 | F14: 101.41 | G14: 141.98 | I14: 2218 | J14: =K14/2 -> 48 | K14: 96 | L14: 7 | M14: 5.3936275 | N14: 5.2983174 | O14: 5.3783755 | P14: 7.7043612 | Q14: 0 | R14: 0 | S14: 2399 | T14: 4.5627845 | U14: 2.2170272
A15: 45292 | B15: 220 | C15: 200 | D15: 216.67 | F15: 101.47 | G15: 142.06 | I15: 2171 | J15: =K15/2 -> 47 | K15: 94 | L15: 5 | M15: 5.3936275 | N15: 5.2983174 | O15: 5.3783755 | P15: 7.6829432 | Q15: 0 | R15: 0 | S15: 2572 | T15: 4.5403116 | U15: 2.4212566
A16: 45299 | B16: 220 | C16: 210 | D16: 216.67 | F16: 101.53 | G16: 142.14 | I16: 2229 | J16: =K16/2 -> 47.5 | K16: 95 | L16: 6 | M16: 5.3936275 | N16: 5.3471075 | O16: 5.3783755 | P16: 7.7093083 | Q16: 0 | R16: 0 | S16: 2577 | T16: 4.5508196 | U16: 2.2752139
A17: 45306 | B17: 220 | C17: 210 | D17: 216.67 | F17: 101.59 | G17: 142.22 | I17: 2116 | J17: =K17/2 -> 46.5 | K17: 93 | L17: 7 | M17: 5.3936275 | N17: 5.3471075 | O17: 5.3783755 | P17: 7.6572828 | Q17: 0 | R17: 0 | S17: 2314 | T17: 4.5371055 | U17: 2.3398809
A18: 45313 | B18: 220 | C18: 210 | D18: 216.67 | F18: 101.64 | G18: 142.3 | I18: 2050 | J18: =K18/2 -> 46.5 | K18: 93 | L18: 8 | M18: 5.3936275 | N18: 5.3471075 | O18: 5.3783755 | P18: 7.6255951 | Q18: 0 | R18: 0 | S18: 2466 | T18: 4.5336742 | U18: 2.3145137
A19: 45320 | B19: 220 | C19: 210 | D19: 216.67 | F19: 101.7 | G19: 142.38 | I19: 2300 | J19: =K19/2 -> 47.5 | K19: 95 | L19: 7 | M19: 5.3936275 | N19: 5.3471075 | O19: 5.3783755 | P19: 7.7406644 | Q19: 0 | R19: 0 | S19: 2275 | T19: 4.5542979 | U19: 2.2834023
... A25: 45362 | B25: 220 | C25: 210 | D25: 226.67 | F25: 102.05 | G25: 142.87 | I25: 2788 | J25: =K25/2 -> 49.5 | K25: 99 | L25: 8 | M25: 5.3936275 | N25: 5.3471075 | O25: 5.4234952 | P25: 7.9330798 | Q25: 0 | R25: 0 | S25: 2342 | T25: 4.5938059 | U25: 2.4185888
A26: 45369 | B26: 220 | C26: 210 | D26: 226.67 | E26: Holi (build-up) | F26: 102.11 | G26: 142.95 | I26: 3447 | J26: =K26/2 -> 49 | K26: 98 | L26: 7 | M26: 5.3936275 | N26: 5.3471075 | O26: 5.4234952 | P26: 8.1452596 | Q26: 0 | R26: 1 | S26: 2593 | T26: 4.5862931 | U26: 2.5408143
A27: 45376 | B27: 220 | C27: 210 | D27: 226.67 | E27: Holi (peak week) | F27: 102.16 | G27: 143.03 | I27: 4504 | J27: =K27/2 -> 48.5 | K27: 97 | L27: 9 | M27: 5.3936275 | N27: 5.3471075 | O27: 5.4234952 | P27: 8.4127212 | Q27: 1 | R27: 0 | S27: 3033 | T27: 4.5739891 | U27: 2.6567569
A28: 45383 | B28: 220 | C28: 210 | D28: 226.67 | F28: 102.22 | G28: 143.11 | I28: 2174 | J28: =K28/2 -> 48 | K28: 96 | L28: 9.8 | M28: 5.3936275 | N28: 5.3471075 | O28: 5.4234952 | P28: 7.6843241 | Q28: 0 | R28: 0 | S28: 2285 | T28: 4.5679874 | U28: 2.2823824
A29: 45390 | B29: 230 | C29: 210 | D29: 226.67 | F29: 102.28 | G29: 143.19 | H29: Regular increase | I29: 2207 | J29: =K29/2 -> 50.5 | K29: 101 | L29: 11 | M29: 5.4380793 | N29: 5.3471075 | O29: 5.4234952 | P29: 7.6993894 | Q29: 0 | R29: 0 | S29: 2293 | T29: 4.6145263 | U29: 2.2170272
A30: 45397 | B30: 230 | C30: 210 | D30: 226.67 | F30: 102.34 | G30: 143.27 | I30: 2519 | J30: =K30/2 -> 50.5 | K30: 101 | L30: 8 | M30: 5.4380793 | N30: 5.3471075 | O30: 5.4234952 | P30: 7.8316173 | Q30: 0 | R30: 0 | S30: 2312 | T30: 4.6130391 | U30: 2.4051417
A31: 45404 | B31: 230 | C31: 210 | D31: 226.67 | F31: 102.4 | G31: 143.36 | I31: 2570 | J31: =K31/2 -> 50.5 | K31: 101 | L31: 9 | M31: 5.4380793 | N31: 5.3471075 | O31: 5.4234952 | P31: 7.8516612 | Q31: 0 | R31: 0 | S31: 2326 | T31: 4.6150215 | U31: 2.4069451
A32: 45411 | B32: 230 | C32: 210 | D32: 226.67 | F32: 102.46 | G32: 143.44 | I32: 2366 | J32: =K32/2 -> 51 | K32: 102 | L32: 10 | M32: 5.4380793 | N32: 5.3471075 | O32: 5.4234952 | P32: 7.768956 | Q32: 0 | R32: 0 | S32: 2660 | T32: 4.6265402 | U32: 2.3194422
A33: 45418 | B33: 230 | C33: 210 | D33: 226.67 | F33: 102.51 | G33: 143.52 | I33: 2375 | J33: =K33/2 -> 52 | K33: 104 | L33: 12 | M33: 5.4380793 | N33: 5.3471075 | O33: 5.4234952 | P33: 7.7727527 | Q33: 0 | R33: 0 | S33: 2102 | T33: 4.6401512 | U33: 2.3749058
A34: 45425 | B34: 230 | C34: 210 | D34: 226.67 | F34: 102.57 | G34: 143.6 | I34: 2409 | J34: =K34/2 -> 52 | K34: 104 | L34: 12 | M34: 5.4380793 | N34: 5.3471075 | O34: 5.4234952 | P34: 7.786967 | Q34: 0 | R34: 0 | S34: 1995 | T34: 4.6466 | U34: 2.3951643
A35: 45432 | B35: 230 | C35: 210 | D35: 226.67 | F35: 102.63 | G35: 143.68 | I35: 2553 | J35: =K35/2 -> 53 | K35: 106 | L35: 11 | M35: 5.4380793 | N35: 5.3471075 | O35: 5.4234952 | P35: 7.8450244 | Q35: 0 | R35: 0 | S35: 1924 | T35: 4.662023 | U35: 2.3997118
A36: 45439 | B36: 230 | C36: 210 | D36: 226.67 | F36: 102.69 | G36: 143.76 | I36: 2597 | J36: =K36/2 -> 53.5 | K36: 107 | L36: 10 | M36: 5.4380793 | N36: 5.3471075 | O36: 5.4234952 | P36: 7.8621122 | Q36: 0 | R36: 0 | S36: 2126 | T36: 4.6747895 | U36: 2.4078456
A37: 45446 | B37: 230 | C37: 210 | D37: 226.67 | F37: 102.75 | G37: 143.85 | I37: 2453 | J37: =K37/2 -> 52 | K37: 104 | L37: 9.96 | M37: 5.4380793 | N37: 5.3471075 | O37: 5.4234952 | P37: 7.805067 | Q37: 0 | R37: 0 | S37: 2283 | T37: 4.6480381 | U37: 2.2985771
A38: 45453 | B38: 230 | C38: 210 | D38: 226.67 | F38: 102.81 | G38: 143.93 | I38: 2653 | J38: =K38/2 -> 53 | K38: 106 | L38: 9 | M38: 5.4380793 | N38: 5.3471075 | O38: 5.4234952 | P38: 7.8834464 | Q38: 0 | R38: 0 | S38: 2125 | T38: 4.6608887 | U38: 2.457878
A39: 45460 | B39: 230 | C39: 210 | D39: 226.67 | F39: 102.86 | G39: 144.01 | I39: 2506 | J39: =K39/2 -> 54 | K39: 108 | L39: 10 | M39: 5.4380793 | N39: 5.3471075 | O39: 5.4234952 | P39: 7.8264431 | Q39: 0 | R39: 0 | S39: 1972 | T39: 4.6801849 | U39: 2.2375131
A40: 45467 | B40: 230 | C40: 210 | D40: 226.67 | F40: 102.92 | G40: 144.09 | I40: 2529 | J40: =K40/2 -> 52.5 | K40: 105 | L40: 11 | M40: 5.4380793 | N40: 5.3471075 | O40: 5.4234952 | P40: 7.8355792 | Q40: 0 | R40: 0 | S40: 1934 | T40: 4.6515766 | U40: 2.4069451
A41: 45474 | B41: 230 | C41: 210 | D41: 226.67 | F41: 102.98 | G41: 144.17 | I41: 2612 | J41: =K41/2 -> 53.5 | K41: 107 | L41: 12 | M41: 5.4380793 | N41: 5.3471075 | O41: 5.4234952 | P41: 7.8678715 | Q41: 0 | R41: 0 | S41: 2343 | T41: 4.671426 | U41: 2.3786198
... A46: 45509 | B46: 230 | C46: 220 | D46: 226.67 | F46: 103.27 | G46: 144.58 | I46: 2754 | J46: =K46/2 -> 55.5 | K46: 111 | L46: 13 | M46: 5.4380793 | N46: 5.3936275 | O46: 5.4234952 | P46: 7.9208097 | Q46: 0 | R46: 0 | S46: 2409 | T46: 4.7071851 | U46: 2.2082744
A47: 45516 | B47: 230 | C47: 220 | D47: 226.67 | E47: Raksha Bandhan (build-up) | F47: 103.33 | G47: 144.67 | I47: 3520 | J47: =K47/2 -> 54.5 | K47: 109 | L47: 14 | M47: 5.4380793 | N47: 5.3936275 | O47: 5.4234952 | P47: 8.1662163 | Q47: 0 | R47: 1 | S47: 2680 | T47: 4.6929979 | U47: 2.5710843
A48: 45523 | B48: 230 | C48: 220 | D48: 226.67 | E48: Raksha Bandhan (peak week) | F48: 103.39 | G48: 144.75 | I48: 5170 | J48: =K48/2 -> 56 | K48: 112 | L48: 15 | M48: 5.4380793 | N48: 5.3936275 | O48: 5.4234952 | P48: 8.550628 | Q48: 1 | R48: 0 | S48: 3219 | T48: 4.7213519 | U48: 2.5649494
A49: 45530 | B49: 230 | C49: 220 | D49: 226.67 | F49: 103.45 | G49: 144.83 | I49: 2537 | J49: =K49/2 -> 55.5 | K49: 111 | L49: 12 | M49: 5.4380793 | N49: 5.3936275 | O49: 5.4234952 | P49: 7.8387376 | Q49: 0 | R49: 0 | S49: 2496 | T49: 4.7100706 | U49: 2.3456446
...

Sheet montecarlo
A1: shelf | B1: legal | C1: pretax_ok | D1: E_units | E1: E_profit | F1: P5 | G1: P95 | H1: CVaR5 | I1: P_minvol | J1: P_minprofit | K1: P_joint | L1: P_over_cap | M1: P_over_maxprofit
A2: 288 | B2: needs new MRP | C2: TRUE | D2: 13032.507 | E2: 762492.76 | F2: 613761.1 | G2: 919529.02 | H2: 580589.47 | I2: 0.50944 | J2: 0.88738 | K2: 0.50016 | L2: 0 | M2: 0.17204
A3: 287 | B3: needs new MRP | C3: TRUE | D3: 13087.675 | E3: 756399.19 | F3: 607486.33 | G3: 913520.74 | H3: 574549.52 | I3: 0.5406 | J3: 0.87412 | K3: 0.52636 | L3: 0 | M3: 0.1567
A4: 286 | B4: needs new MRP | C4: TRUE | D4: 13143.281 | E4: 750250.86 | F4: 601295.8 | G4: 907569.1 | H4: 568440.05 | I4: 0.57404 | J4: 0.8586 | K4: 0.55256 | L4: 0 | M4: 0.14252
A5: 285 | B5: needs new MRP | C5: TRUE | D5: 13199.328 | E5: 744047.1 | F5: 595043.38 | G5: 901290.98 | H5: 562258.52 | I5: 0.60658 | J5: 0.8432 | K5: 0.57656 | L5: 0 | M5: 0.1295
A6: 284 | B6: needs new MRP | C6: TRUE | D6: 13255.822 | E6: 737787.25 | F6: 588684.66 | G6: 894962.6 | H6: 556002.99 | I6: 0.63806 | J6: 0.8266 | K6: 0.59666 | L6: 0 | M6: 0.11644
A7: 283 | B7: needs new MRP | C7: TRUE | D7: 13312.768 | E7: 731470.6 | F7: 582505.74 | G7: 888636.56 | H7: 549672.91 | I7: 0.67002 | J7: 0.8074 | K7: 0.61398 | L7: 0 | M7: 0.10436
A8: 282 | B8: needs new MRP | C8: TRUE | D8: 13370.171 | E8: 725096.46 | F8: 576184.41 | G8: 882163.76 | H8: 543265.89 | I8: 0.69958 | J8: 0.78686 | K8: 0.62588 | L8: 0 | M8: 0.09294
A9: 281 | B9: needs new MRP | C9: TRUE | D9: 13428.037 | E9: 718664.13 | F9: 569693.05 | G9: 875791.99 | H9: 536781.48 | I9: 0.72822 | J9: 0.76618 | K9: 0.63466 | L9: 0 | M9: 0.08228
A10: 280 | B10: ok | C10: TRUE | D10: 13486.372 | E10: 712172.86 | F10: 563062.72 | G10: 869430.89 | H10: 530220.24 | I10: 0.75522 | J10: 0.74264 | K10: 0.6362 | L10: 0 | M10: 0.07276
A11: 279 | B11: ok | C11: TRUE | D11: 13545.18 | E11: 705621.94 | F11: 556412.66 | G11: 863227.94 | H11: 523584.51 | I11: 0.78182 | J11: 0.71924 | K11: 0.63516 | L11: 0 | M11: 0.06432
A12: 278 | B12: ok | C12: TRUE | D12: 13604.467 | E12: 699010.62 | F12: 549571.06 | G12: 856664.32 | H12: 516871.84 | I12: 0.80538 | J12: 0.69304 | K12: 0.627 | L12: 0 | M12: 0.05682
A13: 277 | B13: ok | C13: TRUE | D13: 13664.239 | E13: 692338.11 | F13: 542830.69 | G13: 849921.97 | H13: 510086.02 | I13: 0.82762 | J13: 0.66624 | K13: 0.6153 | L13: 2e-05 | M13: 0.05
... A25: 265 | B25: ok | C25: TRUE | D25: 14421.323 | E25: 607189.89 | F25: 455903.61 | G25: 766992.64 | H25: 422529.25 | I25: 0.97522 | J25: 0.31906 | K25: 0.3189 | L25: 0.0008 | M25: 0.0067

Sheet Definitions
A1: 05 — DEFINITIONS FOR NON-ECONICS USERS
A3: Term | B3: Simple definition | C3: Examples | D3: Use in pricing model | E3: Usually entered as | F3: Notes
A4: Fixed cost | B4: Generally stable with unit volume within the selected operating range and period. | C4: Rent, permanent salaries, insurance, depreciation | D4: Period-level cost; used in break-even and profit optimization | E4: ₹ / period | F4: Can become step/mixed at capacity thresholds.
A5: Variable cost | B5: Generally changes with units produced or sold. | C5: Raw material, packaging, per-unit logistics, marketplace fee | D5: Cost per unit / function of quantity | E5: ₹ / unit | F5: Packaging is usually variable when one package is needed per unit.
A6: Packaging cost | B6: Physical packaging and consumables. | C6: Pouch, carton, label, seal, bottle, cap, tray | D6: Variable cost per unit | E6: ₹ / unit | F6: Separate it for transparency and optimization.
A7: Fixed labour | B7: Labour cost not directly scaling with units in the relevant range. | C7: Plant manager salary, permanent admin salary | D7: Fixed cost / period | E7: ₹ / period | F7: May become semi-variable with overtime or extra shifts.
A8: Variable labour | B8: Labour paid in proportion to output or directly productive hours. | C8: Piece-rate workers, output-linked packing labour | D8: Variable cost / unit or function of Q | E8: ₹ / unit | F8: Useful for operations-aware pricing.
A9: Step / semi-variable cost | B9: Cost changes in jumps after a threshold. | C9: Overtime, second shift, extra warehouse | D9: Piecewise cost function | E9: Rule / amount | F9: Keep separate where a simple fixed/variable classification is misleading.
A10: Target volume / period | B10: Expected saleable units during the selected planning/cost period. | C10: 10,000 units/month | D10: Fixed-cost allocation and break-even analysis | E10: units / period | F10: Planning assumption; not the final demand forecast.
A11: Minimum production | B11: Lowest feasible or contracted volume in a period. | C11: 1,000 units/month | D11: Hard optimization constraint | E11: units / period | F11: Use only if operationally/contractually real.
A12: Maximum production | B12: Physical/operational output ceiling in a period. | C12: 10,000 units/month | D12: Hard optimization constraint | E12: units / period | F12: Can come from equipment, labour or storage.
A13: GST / tax | B13: Tax rate applied to the relevant tax base. | C13: 5%, 12%, 18% | D13: Separates base price from customer-facing price | E13: % | F13: Actual applicability must be validated for the product/jurisdiction.
A14: Price leader | B14: Competitor whose pricing provides an important market reference. | C14: Largest brand in a category | D14: Relative price / competitive response features | E14: Name + price | F14: Leadership is a market fact, not automatically a pricing target.
A15: Price elasticity | B15: Approximate % change in demand from a 1% price change. | C15: Elasticity = -1.5 | D15: Demand response estimation | E15: Estimated later | F15: Use company evidence first; external values are priors/sanity checks.

Sheet Dashboard
A1: PRICING CONTEXT — LIVE SUMMARY
A3: Metric | B3: Value | C3: Metric | D3: Value | E3: Metric | F3: Value | G3: Metric | H3: Value
A4: Company | B4: =Company_Context!B5 -> bishanlal babulal | C4: Product | D4: =Company_Context!B7 -> 1kg bikaneri bhujia | E4: Period | F4: =Company_Context!B11 -> rajasthan particulary bikaner | G4: Readiness | H4: =#REF! -> #REF!
A5: Current base price | B5: =Company_Context!B16 -> 267 | C5: GST % | D5: =Company_Context!B17 -> 5 | E5: Customer price | F5: =Company_Context!B22 -> 280.35 | G5: Leader | H5: =Company_Context!F6 -> bikaji
A6: Variable cost / unit | B6: =Cost_Structure!C18 -> 180.7 | C6: Fixed cost / period | D6: =Cost_Structure!C30 -> 448000 | E6: Target volume | F6: =Cost_Structure!B6 -> 15000 | G6: Break-even volume | H6: =Cost_Structure!B41 -> 56.433333
A7: Full cost / unit | B7: =Cost_Structure!B39 -> 210.56667 | C7: Contribution / unit | D7: =Cost_Structure!B40 -> 86.3 | E7: Effective max capacity | F7: =#REF! -> #REF! | G7: Min margin | H7: =#REF! -> #REF!
A8: Min production | B8: =#REF! -> #REF! | C8: Max production | D8: =#REF! -> #REF! | E8: Supplier MOQ | F8: =#REF! -> #REF! | G8: Max price vs leader | H8: =#REF! -> #REF!
A11: How the workbook feeds the pricing engine
A12: Stage | B12: Uses this workbook | C12: Output | D12: Next step
A13: 1. Context | B13: Company + product + leader + tax | C13: Structured pricing profile | D13: Validate data
A14: 2. Cost | B14: Variable + fixed + packaging + labour | C14: Cost function + break-even | D14: Constrain optimization
A15: 3. Demand | B15: Historical price + quantity + context | C15: Forecast + demand response | D15: Elasticity / causal models
A16: 4. Competition | B16: Leader / competitor prices | C16: Relative price + leader gap | D16: Competitive constraints
A17: 5. Optimization | B17: Demand + cost + constraints | C17: Candidate price set | D17: Sensitivity + Monte Carlo
A18: 6. Explanation | B18: Model outputs + context | C18: Human-readable explanation | D18: Human review / decision
